Workbook

Sheet Read Me
A1: Japan Sourcing Trip — Russel's inventory
A3: Scope | B3: Russel's own cards only. Excludes Kenshin, Nico, Eugene and the Gibbs client order entirely.
A4: Period | B4: 27 July – 1 August 2026 · Tokyo and Osaka. Day 5 was travel, no buying.
A5: Lines | B5: 107 purchase lines covering 169 physical items.
A7: Categories
A8: PSA Slab | B8: Professionally graded and encapsulated. 14 lines, 15 items.
A9: Single | B9: Raw or shop-graded loose cards. 77 lines, 94 items.
A10: Sealed | B10: Unopened boxes. 16 lines, 60 items. Neither of the two categories asked for, so recorded separately rather than forced into one.
A12: Costing
A13: Sticker ¥ | B13: Shelf price before any tax-free discount.
A14: Paid ¥ | B14: What was actually paid. On 免税 receipts this is the sticker net of the 9.09% deduction, split per line and reconciled to the printed receipt total.
A15: FX | B15: 0.380 for Days 1–4, 0.385 for Day 6, both per Russel. No card has posted in pesos yet, so peso figures on card lines are provisional.
A16: Cost ₱ | B16: =Paid ¥ × FX. Formula, not a typed number.
A17: Unit ₱ | B17: =Cost ₱ ÷ Qty. Use this for per-item landed cost.
A19: Not included
A20: Overhead | B20: Meals, transport and trip expenses are deliberately NOT capitalised into these costs. Every figure here is ex-overhead by decision.
A21: Duties | B21: Nothing for PH import duty, freight or grading is included.
A23: Watch
A24: Unnamed | B24: D6-23, D6-24, D6-33, D6-34 and D3-23 carry no card name — the receipts did not print one. Confirm before listing.
A25: 50% stakes | B25: D6-33 and D6-34 are held half with Eugene. Only Russel's half is costed here; the physical cards are whole.
A26: No receipt | B26: D3-22 and D3-23 have no receipt, cash per Russel.

Sheet Inventory
A1: Line | B1: Day | C1: Date | D1: Store | E1: Item | F1: Detail / Set | G1: Category | H1: Qty | I1: Sticker ¥ | J1: Paid ¥ | K1: FX | L1: Cost ₱ | M1: Unit ₱ | N1: Tax | O1: Payment
A2: PSA SLAB — 14 lines, 15 items
A3: D4-16 | B3: 4 | C3: 30-Jul-2026 | D3: スニーダンクトレカ 秋葉原店 19:52 | E3: Snorlax 1st Ed — PSA 10 | F3: カビゴン(1ED) PSA10 · U中古 | G3: PSA Slab | H3: 1 | I3: 260000 | J3: 236364 | K3: 0.38 | L3: =J3*K3 | M3: =L3/H3 | N3: 免税 | O3: Cash + Mastercard (split)
A4: D1-13 | B4: 1 | C4: 27-Jul-2026 | D4: Card Collect | E4: Charizard — PCG 25th Anniversary #001 | F4: 2021 JP · PSA 10 GEM MT | G4: PSA Slab | H4: 1 | I4: 133000 | J4: 120910 | K4: 0.38 | L4: =J4*K4 | M4: =L4/H4 | N4: 免税 | O4: Cash
A5: D4-17 | B5: 4 | C5: 30-Jul-2026 | D5: スニーダンクトレカ 秋葉原店 19:52 | E5: Snorlax 1st Ed — PSA 10 | F5: カビゴン(1ED) PSA10 · C中古 | G5: PSA Slab | H5: 1 | I5: 100000 | J5: 90909 | K5: 0.38 | L5: =J5*K5 | M5: =L5/H5 | N5: 免税 | O5: Cash + Mastercard (split)
A6: D4-05 | B6: 4 | C6: 30-Jul-2026 | D6: スニーダンクトレカ 秋葉原店 13:18 | E6: Latias — graded | F6: ポケカ鑑定品-125中古 · PCG | G6: PSA Slab | H6: 1 | I6: 90000 | J6: 81818 | K6: 0.38 | L6: =J6*K6 | M6: =L6/H6 | N6: 免税 | O6: Cash
A7: D4-06 | B7: 4 | C7: 30-Jul-2026 | D7: スニーダンクトレカ 秋葉原店 13:18 | E7: Latios — graded | F7: ポケカ鑑定品-125中古 · PCG | G7: PSA Slab | H7: 1 | I7: 80000 | J7: 72728 | K7: 0.38 | L7: =J7*K7 | M7: =L7/H7 | N7: 免税 | O7: Cash
A8: D1-08 | B8: 1 | C8: 27-Jul-2026 | D8: SNKRDUNK Toreca Akihabara | E8: Luffy Elbaf | F8: One Piece Day promo · PSA 10 | G8: PSA Slab | H8: 1 | I8: 55000 | J8: 50000 | K8: 0.38 | L8: =J8*K8 | M8: =L8/H8 | N8: 免税 | O8: Cash (via Nico, repaid)
A9: D4-18 | B9: 4 | C9: 30-Jul-2026 | D9: スニーダンクトレカ 秋葉原店 19:52 | E9: Snorlax promo — PSA 10 | F9: カビゴン PSA10 (PR) · 中古 | G9: PSA Slab | H9: 1 | I9: 35000 | J9: 31818 | K9: 0.38 | L9: =J9*K9 | M9: =L9/H9 | N9: 免税 | O9: Cash + Mastercard (split)
A10: D1-10 | B10: 1 | C10: 27-Jul-2026 | D10: SNKRDUNK Toreca Akihabara | E10: Squirtle SVG #52 | F10: Pokémon · PSA 10 | G10: PSA Slab | H10: 1 | I10: 28000 | J10: 25455 | K10: 0.38 | L10: =J10*K10 | M10: =L10/H10 | N10: 免税 | O10: Cash (via Nico, repaid)
A11: D2-13 | B11: 2 | C11: 28-Jul-2026 | D11: シンソク新宿店 18:53 | E11: Bulbasaur — AR spec | F11: フシギダネ AR仕様 · PSA 10 | G11: PSA Slab | H11: 1 | I11: 27800 | J11: 25273 | K11: 0.38 | L11: =J11*K11 | M11: =L11/H11 | N11: 免税 | O11: JCB 1608
A12: D1-09 | B12: 1 | C12: 27-Jul-2026 | D12: SNKRDUNK Toreca Akihabara | E12: Eevee Promo | F12: Prismatic Evolutions ETB · PSA 10 | G12: PSA Slab | H12: 1 | I12: 20000 | J12: 18182 | K12: 0.38 | L12: =J12*K12 | M12: =L12/H12 | N12: 免税 | O12: Cash (via Nico, repaid)
A13: D2-17 | B13: 2 | C13: 28-Jul-2026 | D13: シンソク新宿店 18:53 | E13: Regigigas | F13: レジギガス · PSA 10 | G13: PSA Slab | H13: 1 | I13: 19800 | J13: 18000 | K13: 0.38 | L13: =J13*K13 | M13: =L13/H13 | N13: 免税 | O13: JCB 1608
A14: D2-18 | B14: 2 | C14: 28-Jul-2026 | D14: シンソク新宿店 18:53 | E14: Oshawott | F14: ミジュマル · PSA 10 | G14: PSA Slab | H14: 1 | I14: 14800 | J14: 13455 | K14: 0.38 | L14: =J14*K14 | M14: =L14/H14 | N14: 免税 | O14: JCB 1608
... A16: D1-01 | B16: 1 | C16: 27-Jul-2026 | D16: woorth Akihabara | E16: Clefairy AR | F16: M3 086/080 · PSA 10 | G16: PSA Slab | H16: 1 | I16: 8980 | J16: 8980 | K16: 0.38 | L16: =J16*K16 | M16: =L16/H16 | N16: 税込 | O16: Mastercard 4170
A17: Subtotal — PSA Slab | H17: =SUM(H3:H16) | I17: =SUM(I3:I16) | J17: =SUM(J3:J16) | L17: =SUM(L3:L16)
A19: SEALED — 16 lines, 60 items
A20: D2-01 | B20: 2 | C20: 28-Jul-2026 | D20: シンソク新宿店 18:45 | E20: Pokémon Stamp Box | F20: ポケモン切手BOX · sealed | G20: Sealed | H20: 1 | I20: 528000 | J20: 480000 | K20: 0.38 | L20: =J20*K20 | M20: =L20/H20 | N20: 免税 | O20: Cash
A21: D4-04 | B21: 4 | C21: 30-Jul-2026 | D21: スニーダンクトレカ 秋葉原店 14:51 | E21: MEGA Dream ex ×10 — high-class boxes | F21: ¥16,000 each · 中古 | G21: Sealed | H21: 10 | I21: 160000 | J21: 145455 | K21: 0.38 | L21: =J21*K21 | M21: =L21/H21 | N21: 免税 | O21: Mastercard
A22: D4-01 | B22: 4 | C22: 30-Jul-2026 | D22: シンソク秋葉原2号店 | E22: Black Bolt Deluxe ×4 — booster boxes | F22: SV11B · ¥29,500 each | G22: Sealed | H22: 4 | I22: 118000 | J22: 107273 | K22: 0.38 | L22: =J22*K22 | M22: =L22/H22 | N22: 免税 | O22: Cash
A23: D4-02 | B23: 4 | C23: 30-Jul-2026 | D23: シンソク秋葉原2号店 | E23: MEGA Dream ex ×6 — high-class boxes | F23: M2a · ¥15,200 each | G23: Sealed | H23: 6 | I23: 91200 | J23: 82909 | K23: 0.38 | L23: =J23*K23 | M23: =L23/H23 | N23: 免税 | O23: Cash
A24: D6-01 | B24: 6 | C24: 01-Aug-2026 | D24: AMTAF 日本橋 | E24: Abyss Eye ×9 — sealed boxes | F24: M5 · ¥8,910 each | G24: Sealed | H24: 9 | I24: 80190 | J24: 72900 | K24: 0.385 | L24: =J24*K24 | M24: =L24/H24 | N24: 免税 | O24: Cash
A25: D4-19 | B25: 4 | C25: 30-Jul-2026 | D25: スニーダンクトレカ 秋葉原店 20:05 | E25: MEGA Dream ex ×5 — high-class boxes | F25: ¥16,000 each · 中古 | G25: Sealed | H25: 5 | I25: 80000 | J25: 72727 | K25: 0.38 | L25: =J25*K25 | M25: =L25/H25 | N25: 免税 | O25: Mastercard
A26: D6-02 | B26: 6 | C26: 01-Aug-2026 | D26: AMTAF 日本橋 | E26: Nihil Zero Munikis ×8 — sealed boxes | F26: M3 · ¥9,240 each | G26: Sealed | H26: 8 | I26: 73920 | J26: 67200 | K26: 0.385 | L26: =J26*K26 | M26: =L26/H26 | N26: 免税 | O26: Cash
A27: D6-03 | B27: 6 | C27: 01-Aug-2026 | D27: AMTAF 日本橋 | E27: Ninja Spinner ×5 — sealed boxes | F27: M4 · ¥10,670 each | G27: Sealed | H27: 5 | I27: 53350 | J27: 48400 | K27: 0.385 | L27: =J27*K27 | M27: =L27/H27 | N27: 免税 | O27: Cash
A28: D4-20 | B28: 4 | C28: 30-Jul-2026 | D28: スニーダンクトレカ 秋葉原店 20:05 | E28: Nihil Zero Munikis ×4 — boxes | F28: ¥9,800 each · 中古 | G28: Sealed | H28: 4 | I28: 39200 | J28: 35637 | K28: 0.38 | L28: =J28*K28 | M28: =L28/H28 | N28: 免税 | O28: Mastercard
A29: D2-14 | B29: 2 | C29: 28-Jul-2026 | D29: シンソク新宿店 18:53 | E29: Black Bolt Deluxe — booster box | F29: 拡張パックデラックス SV11B | G29: Sealed | H29: 1 | I29: 28000 | J29: 25455 | K29: 0.38 | L29: =J29*K29 | M29: =L29/H29 | N29: 免税 | O29: JCB 1608
A30: D4-03 | B30: 4 | C30: 30-Jul-2026 | D30: シンソク秋葉原2号店 | E30: Mega Brave ×2 — booster boxes | F30: M1L · ¥13,500 each | G30: Sealed | H30: 2 | I30: 27000 | J30: 24548 | K30: 0.38 | L30: =J30*K30 | M30: =L30/H30 | N30: 免税 | O30: Cash
A31: D4-21 | B31: 4 | C31: 30-Jul-2026 | D31: カードコレクト HANARE | E31: Black Bolt — sealed box | F31: SV11B · 未開封BOX | G31: Sealed | H31: 1 | I31: 25800 | J31: 23455 | K31: 0.38 | L31: =J31*K31 | M31: =L31/H31 | N31: 免税 | O31: Cash
... A35: D2-20 | B35: 2 | C35: 28-Jul-2026 | D35: シンソク新宿店 18:57 | E35: MEGA Dream ex — high-class box | F35: ハイクラスパック M2a | G35: Sealed | H35: 1 | I35: 15500 | J35: 14092 | K35: 0.38 | L35: =J35*K35 | M35: =L35/H35 | N35: 免税 | O35: JCB 1608
A36: Subtotal — Sealed | H36: =SUM(H20:H35) | I36: =SUM(I20:I35) | J36: =SUM(J20:J35) | L36: =SUM(L20:L35)
A38: SINGLE — 77 lines, 94 items
A39: D6-23 | B39: 6 | C39: 01-Aug-2026 | D39: トレカSunrise 大阪日本橋 | E39: SR/SA 188/173 | F39: 中古 · card name not printed | G39: Single | H39: 1 | I39: 42800 | J39: 42155 | K39: 0.385 | L39: =J39*K39 | M39: =L39/H39 | N39: 税込 | O39: Cash
A40: D6-24 | B40: 6 | C40: 01-Aug-2026 | D40: トレカSunrise 大阪日本橋 | E40: SR 092/081 | F40: 中古 · card name not printed | G40: Single | H40: 1 | I40: 40000 | J40: 39397 | K40: 0.385 | L40: =J40*K40 | M40: =L40/H40 | N40: 税込 | O40: Cash
A41: D2-02 | B41: 2 | C41: 28-Jul-2026 | D41: シンソク新宿店 18:50 | E41: Giratina VSTAR | F41: ギラティナVSTAR · グレードA | G41: Single | H41: 1 | I41: 26800 | J41: 24364 | K41: 0.38 | L41: =J41*K41 | M41: =L41/H41 | N41: 免税 | O41: Mastercard 4170
A42: D6-04 | B42: 6 | C42: 01-Aug-2026 | D42: ドラゴンスターなんば | E42: Pikachu | F42: ピカチュウ 208/S-P · キズアリ | G42: Single | H42: 1 | I42: 17980 | J42: 17980 | K42: 0.385 | L42: =J42*K42 | M42: =L42/H42 | N42: 税込 | O42: Credit
A43: D6-05 | B43: 6 | C43: 01-Aug-2026 | D43: ドラゴンスターなんば | E43: Gengar ex SR ×3 | F43: ゲンガーex 088/071 SR · ¥5,480 ea | G43: Single | H43: 3 | I43: 16440 | J43: 16440 | K43: 0.385 | L43: =J43*K43 | M43: =L43/H43 | N43: 税込 | O43: Credit
A44: D6-06 | B44: 6 | C44: 01-Aug-2026 | D44: ドラゴンスターなんば | E44: Maushold AR ×5 | F44: イッカネズミ 081/071 AR · ¥2,980 ea | G44: Single | H44: 5 | I44: 14900 | J44: 14900 | K44: 0.385 | L44: =J44*K44 | M44: =L44/H44 | N44: 税込 | O44: Credit
A45: D2-03 | B45: 2 | C45: 28-Jul-2026 | D45: シンソク新宿店 18:50 | E45: Arceus VSTAR | F45: アルセウスVSTAR · グレードA | G45: Single | H45: 1 | I45: 15800 | J45: 14364 | K45: 0.38 | L45: =J45*K45 | M45: =L45/H45 | N45: 免税 | O45: Mastercard 4170
A46: D6-15 | B46: 6 | C46: 01-Aug-2026 | D46: カードショップはっちゃ 日本橋 | E46: Eevee | F46: イーブイ 062/SV-P · 無 | G46: Single | H46: 1 | I46: 12800 | J46: 12800 | K46: 0.385 | L46: =J46*K46 | M46: =L46/H46 | N46: 税込 | O46: Credit
...

Sheet Summary
A1: Russel's inventory — summary
A2: All figures pull from the Inventory tab.
A4: By category
A5: Category | B5: Lines | C5: Items | D5: Paid ¥ | E5: Cost ₱
A6: PSA Slab | B6: =COUNTIFS(Inventory!$G$2:$G$118,$A6) | C6: =SUMIFS(Inventory!$H$2:$H$118,Inventory!$G$2:$G$118,$A6) | D6: =SUMIFS(Inventory!$J$2:$J$118,Inventory!$G$2:$G$118,$A6) | E6: =SUMIFS(Inventory!$L$2:$L$118,Inventory!$G$2:$G$118,$A6)
A7: Sealed | B7: =COUNTIFS(Inventory!$G$2:$G$118,$A7) | C7: =SUMIFS(Inventory!$H$2:$H$118,Inventory!$G$2:$G$118,$A7) | D7: =SUMIFS(Inventory!$J$2:$J$118,Inventory!$G$2:$G$118,$A7) | E7: =SUMIFS(Inventory!$L$2:$L$118,Inventory!$G$2:$G$118,$A7)
A8: Single | B8: =COUNTIFS(Inventory!$G$2:$G$118,$A8) | C8: =SUMIFS(Inventory!$H$2:$H$118,Inventory!$G$2:$G$118,$A8) | D8: =SUMIFS(Inventory!$J$2:$J$118,Inventory!$G$2:$G$118,$A8) | E8: =SUMIFS(Inventory!$L$2:$L$118,Inventory!$G$2:$G$118,$A8)
A9: Total | B9: =SUM(B6:B8) | C9: =SUM(C6:C8) | D9: =SUM(D6:D8) | E9: =SUM(E6:E8)
A12: By day
A13: Day | B13: Lines | C13: Items | D13: Paid ¥ | E13: Cost ₱
A14: Day 1 — Akihabara | B14: =COUNTIFS(Inventory!$B$2:$B$118,1) | C14: =SUMIFS(Inventory!$H$2:$H$118,Inventory!$B$2:$B$118,1) | D14: =SUMIFS(Inventory!$J$2:$J$118,Inventory!$B$2:$B$118,1) | E14: =SUMIFS(Inventory!$L$2:$L$118,Inventory!$B$2:$B$118,1)
A15: Day 2 — Shinjuku | B15: =COUNTIFS(Inventory!$B$2:$B$118,2) | C15: =SUMIFS(Inventory!$H$2:$H$118,Inventory!$B$2:$B$118,2) | D15: =SUMIFS(Inventory!$J$2:$J$118,Inventory!$B$2:$B$118,2) | E15: =SUMIFS(Inventory!$L$2:$L$118,Inventory!$B$2:$B$118,2)
A16: Day 3 — Shibuya | B16: =COUNTIFS(Inventory!$B$2:$B$118,3) | C16: =SUMIFS(Inventory!$H$2:$H$118,Inventory!$B$2:$B$118,3) | D16: =SUMIFS(Inventory!$J$2:$J$118,Inventory!$B$2:$B$118,3) | E16: =SUMIFS(Inventory!$L$2:$L$118,Inventory!$B$2:$B$118,3)
A17: Day 4 — Akihabara | B17: =COUNTIFS(Inventory!$B$2:$B$118,4) | C17: =SUMIFS(Inventory!$H$2:$H$118,Inventory!$B$2:$B$118,4) | D17: =SUMIFS(Inventory!$J$2:$J$118,Inventory!$B$2:$B$118,4) | E17: =SUMIFS(Inventory!$L$2:$L$118,Inventory!$B$2:$B$118,4)
A18: Day 6 — Osaka | B18: =COUNTIFS(Inventory!$B$2:$B$118,6) | C18: =SUMIFS(Inventory!$H$2:$H$118,Inventory!$B$2:$B$118,6) | D18: =SUMIFS(Inventory!$J$2:$J$118,Inventory!$B$2:$B$118,6) | E18: =SUMIFS(Inventory!$L$2:$L$118,Inventory!$B$2:$B$118,6)
A19: Total | B19: =SUM(B14:B18) | C19: =SUM(C14:C18) | D19: =SUM(D14:D18) | E19: =SUM(E14:E18)

Sheet Owed to Russel
A1: Owed to Russel
A2: Cards and costs Russel fronted for other people. None of this is in the Inventory tab.
A4: EUGENE — 12 cards + pharmacy
A5: Line | B5: Item | C5: Detail | D5: Amount ¥ | E5: FX | F5: Owed ₱
A6: D2-04 | B6: Gengar LV.38 | C6: ゲンガー LV.38 · Shinsoku Day 2 | D6: 10727 | E6: 0.38 | F6: =D6*E6
A7: D2-11 | B7: Pikachu — Jungle (JP) | C7: 手打用シングル · Shinsoku Day 2 | D7: 1982 | E7: 0.38 | F7: =D7*E7
A8: D6-25 | B8: Pikachu CHR | C8: ピカチュウ 073/071 · Sunrise, net of bill discount | D8: 6402 | E8: 0.385 | F8: =D8*E8
A9: D6-26 | B9: Pikachu PROMO | C9: ピカチュウ 001/SV-P · Sunrise, net of bill discount | D9: 4137 | E9: 0.385 | F9: =D9*E9
A10: D6-27 | B10: Misty's Psyduck AR | C10: カスミのコダック 071/063 · Sunrise | D10: 3447 | E10: 0.385 | F10: =D10*E10
A11: D6-28 | B11: Psyduck AR | C11: コダック 175/165 · Sunrise | D11: 2462 | E11: 0.385 | F11: =D11*E11
A12: D6-29 | B12: Glaceon VSTAR SAR | C12: グレイシアVSTAR 217/172 · no receipt | D12: 5480 | E12: 0.385 | F12: =D12*E12
A13: D6-30 | B13: SAR 245/193 (M2a) | C13: tag katakana unclear · copy 1 of 2 · no receipt | D13: 3680 | E13: 0.385 | F13: =D13*E13
A14: D6-31 | B14: SAR 245/193 (M2a) | C14: tag katakana unclear · copy 2 of 2 · no receipt | D14: 3680 | E14: 0.385 | F14: =D14*E14
A15: D6-32 | B15: Pidgeot ex SAR | C15: ピジョットex 136/108 · no receipt | D15: 2980 | E15: 0.385 | F15: =D15*E15
A16: D6-33 | B16: Single — ¥19,800 · Eugene's 50% | C16: BAR UnKnOwn · name not printed | D16: 9900 | E16: 0.385 | F16: =D16*E16
A17: D6-34 | B17: Single — ¥6,500 · Eugene's 50% | C17: BAR UnKnOwn · name not printed | D17: 3250 | E17: 0.385 | F17: =D17*E17
A18: E7-04 | B18: Pharmacy — furikake ×2 | C18: 1 noritama + 1 yakiniku · Sugi Pharmacy Day 7 | D18: 398 | E18: 0.385 | F18: =D18*E18
A19: Total | D19: =SUM(D6:D18) | F19: =SUM(F6:F18)
A20: Two rates: 0.38 on the Day 2 Shinsoku pair, 0.385 on everything from Osaka. D6-33 and D6-34 are 50/50 — this is his half only.
A22: VM — 2 items
A23: Line | B23: Item | C23: Detail | D23: Amount ¥ | E23: FX | F23: Owed ₱
A24: E2-04 | B24: GU jeans | C24: ¥1,990 sticker, billed net of the 9.09% tax-free discount | D24: 1809 | E24: 0.38 | F24: =D24*E24
A25: E7-03 | B25: Kit Kat ×6 | C25: オトナの甘さ ×3 + 濃い抹茶 ×3 · Sugi Pharmacy Day 7 | D25: 1710 | E25: 0.385 | F25: =D25*E25
A26: Total | D26: =SUM(D24:D25) | F26: =SUM(F24:F25)
A27: Billed on the same tax-free basis Nico and Kenshin settled on, so VM gets the benefit of the exemption.
A29: KIM — pharmacy basket
A30: Line | B30: Item | C30: Detail | D30: Amount ¥ | E30: FX | F30: Owed ₱
A31: E7-02 | B31: Gorilla no Hitotsukami | C31: ゴリラのひとつかみ歌舞 · the single largest item on the receipt | D31: 4878 | E31: 0.385 | F31: =D31*E31
A32: E7-02 | B32: Curel milk makeup remover | C32: キュレル 乳液メイク落とし · receipt line written "Kin", read as Kim | D32: 1464 | E32: 0.385 | F32: =D32*E32
A33: E7-02 | B33: 30 vegetables + S | C33: 30種類の国産野菜+S | D33: 1418 | E33: 0.385 | F33: =D33*E33
A34: E7-02 | B34: Pair Acne Cream W | C34: ペアアクネ クリームW | D34: 957 | E34: 0.385 | F34: =D34*E34
A35: E7-02 | B35: Ashi-rila sheet sakura ×2 | C35: 足リラシート 桜の香り | D35: 385 | E35: 0.385 | F35: =D35*E35
A36: E7-02 | B36: Silcot sponge 40pc | C36: シルコット スポンジ40枚 | D36: 222 | E36: 0.385 | F36: =D36*E36
A37: Total | D37: =SUM(D31:D36) | F37: =SUM(F31:F36)
A38: All from the Sugi Pharmacy run, 2 August. Costs are net of the 3% all-item discount and the tax-free deduction, spread pro-rata.
A40: ADRIAN — 1 item
A41: Line | B41: Item | C41: Detail | D41: Amount ¥ | E41: FX | F41: Owed ₱
A42: E6-02 | B42: びっくりドンキー 道頓堀 | C42: ¥1,140 order + ¥114 pro-rata share of the late-night surcharge | D42: 1254 | E42: 0.385 | F42: =D42*E42
A43: Total | D43: =SUM(D42:D42) | F43: =SUM(F42:F42)
A44: Not requested on this tab, included because it is outstanding on the same basis.
...
